Workbook

Sheet Cover
B2: TEST CASE
B4: Project Name | C4: DOLIBARR | F4: Creator | G4: Bui Anh Hau
B5: Project Code | C5: DOLIBARR | F5: Reviewer/Approver
B6: Document Code | C6: DOLIBARR_TestCase | F6: Issue Date | G6: 46325
F7: Version | G7: 0.2
B10: Record of change
B11: Effective Date | C11: Version | D11: Change Item | E11: *A,D,M | F11: Change description | G11: Reference
B12: 20/10/2026 | C12: 0.1 | D12: Contracts | E12: A | F12: Created 26 Contract test cases | G12: Assignment 6
B13: 30/10/2026 | C13: 0.2 | D13: Contracts | E13: M | F13: Updated test cases to match the automation script; updated Result/Test date after running Selenium IDE script on the demo site | G13: Assignment 7
B14: *A: Added D: Deleted M: Modified

Sheet Test case List
D1: TEST CASE LIST
B3: Project Name | D3: =Cover!C4
B4: Project Code | D4: =Cover!C5
B5: Test Environment Setup Description | D5: Dolibarr ERP & CRM demo 24.0.2 (https://demo.dolibarr.org); Google Chrome; all modules enabled (manual module selection).
B8: No | C8: Function Name | D8: Sheet Name | E8: Description | F8: Pre-Condition
B9: 1 | C9: Contracts | D9: Contracts | E9: Create, list/search/sort, view, edit and delete (draft) contracts. | F9: Sign in; at least 1 Third party exists; the contract list has sample data.

Sheet TestDesign
A1: Requirement Level 1 | B1: Requirement Level 2 | C1: Requirement Level 3 | D1: Test Criteria | E1: Test Type | F1: Note
A2: 1. Contracts | B2: 1.1 Create | C2: Screen / Displaying | D2: Check displaying New contract screen by clicking [New contract or subscription] | E2: Function | F2: CONTRACT_Create_01
C3: Screen / Layout and defaults | D3: Check layout and default values of New contract screen | E3: GUI | F3: CONTRACT_Create_02
C4: Successful create / Minimum data | D4: Check create a draft contract with only the required field (Third party) | E4: Function | F4: CONTRACT_Create_03
C5: Successful create / Note (internal) | D5: Check create a contract with Note (internal) filled | E5: Function | F5: CONTRACT_Create_04
C6: Required field / Third party | D6: Check reject creation when Third party is empty | E6: Function | F6: CONTRACT_Create_05
C7: Result in list | D7: Check new contract is displayed in the Contracts list after creating | E7: Function | F7: CONTRACT_Create_06
C8: Cancel creation | D8: Check cancel a New contract form without saving | E8: Function | F8: CONTRACT_Create_07
C9: Create continuously | D9: Check create two contracts continuously | E9: Function | F9: CONTRACT_Create_08
C10: Field value / Date | D10: Check create a contract with a past Date | E10: Function | F10: CONTRACT_Create_09; EP
C11: Field value / Note (internal) | D11: Check Note (internal) with special characters | E11: Function | F11: CONTRACT_Create_10; EP
C12: Field value / Note (internal) | D12: Check Note (internal) with a very long value (1000 characters) | E12: Function | F12: CONTRACT_Create_11; BVA
B13: 1.2 Read | C13: List display | D13: Check open Contracts list via menu and verify the page title and table | E13: Function | F13: CONTRACT_List_01
C14: List layout | D14: Check layout of Contracts list screen | E14: GUI | F14: CONTRACT_List_02
C15: Search by Ref. | D15: Check find a contract using an existing Ref. | E15: Function | F15: CONTRACT_Search_01
C16: Search / No match | D16: Check return no record for a non-existent Ref. | E16: Function | F16: CONTRACT_Search_02
C17: Search by Third party | D17: Check filter contracts by Third party | E17: Function | F17: CONTRACT_Search_03
C18: Filter by Status | D18: Check filter contracts by Status = Draft | E18: Function | F18: CONTRACT_Search_04
C19: Clear filter | D19: Check clear the applied filter | E19: Function | F19: CONTRACT_Search_05
C20: Sorting | D20: Check change sort by Ref. (ascending, descending) | E20: Function | F20: CONTRACT_Search_06
C21: Sorting | D21: Check change sort by Contract date (ascending, descending) | E21: Function | F21: CONTRACT_Search_07
C22: Details | D22: Check view Contract detail screen from the list | E22: Function | F22: CONTRACT_View_01
C23: Navigation | D23: Check go back to the list from Contract detail screen | E23: Function | F23: CONTRACT_View_02
B24: 1.3 Update | C24: Update Ref. customer | D24: Check modify Ref. customer of a draft contract | E24: Function | F24: CONTRACT_Edit_01
C25: Cancel edit | D25: Check cancel modify Ref. customer | E25: Function | F25: CONTRACT_Edit_02
B26: 1.4 Delete | C26: Delete successful | D26: Check delete a draft contract and confirm | E26: Function | F26: CONTRACT_Delete_01
C27: Cancel deletion | D27: Check cancel delete contract and the contract is preserved | E27: Function | F27: CONTRACT_Delete_02
A28: 2. Purchase Orders | B28: 2.1 Create | C28: Screen / Displaying | D28: Check displaying New purchase order screen and its fields | E28: GUI | F28: Planned - detailed test cases in a later week
C29: Required field / Vendor | D29: Check reject creation when Vendor is empty | E29: Function
C30: Successful create / Minimum data | D30: Check create a draft purchase order with only mandatory fields | E30: Function
C31: Cancel creation | D31: Check cancel create purchase order | E31: Function
B32: 2.2 Read | C32: List display | D32: Check open Purchase Orders list via menu | E32: Function
C33: Search by Ref. | D33: Check find a purchase order by Ref. | E33: Function
C34: Sorting | D34: Check change sort by Ref. (ascending, descending) | E34: Function
B35: 2.3 Update | C35: Order lines | D35: Check add a free text line (quantity 2, unit price 100) - total excl. tax = 200 | E35: Function | F35: Calculation check
C36: Order lines | D36: Check delete an order line - total back to 0 | E36: Function
B37: 2.4 Delete | C37: Delete successful | D37: Check delete a draft purchase order | E37: Function
A38: 3. Supplier Invoices | B38: 3.1 Create | C38: Screen / Displaying | D38: Check displaying New supplier invoice screen and its fields | E38: GUI | F38: Planned - detailed test cases in a later week
C39: Required field / Vendor | D39: Check reject creation when Vendor is empty | E39: Function
C40: Required field / Ref. supplier | D40: Check reject creation when Ref. supplier is empty | E40: Function
...

Sheet Contracts
A2: Module Code | B2: CONTRACT | J2: Passed
A3: Test requirement | B3: Contracts | J3: Failed
A4: Tester | B4: Bui Anh Hau | J4: Blocked
A5: Passed | B5: Failed | C5: Untested | D5: Blocked | E5: Skipped | F5: Number of Test cases | J5: Untested
A6: =COUNTIF(F9:F996,"Passed") | B6: =COUNTIF(F9:F996,"Failed") | C6: =F6-E6-D6-B6-A6 | D6: =COUNTIF(F9:F996,"Blocked") | E6: =COUNTIF(F9:F996,"Skipped") | F6: =COUNTA(A9:A996) | J6: Skipped
A8: ID | B8: Test Case Description | C8: Test Case Procedure | D8: Expected Output | E8: Inter-test case Dependence | F8: Result | G8: Test date | H8: Note
A9: CONTRACT_Create_01 | B9: Check displaying New contract screen by clicking [New contract or subscription] on the left menu | C9: PRE: Signed in the Dolibarr demo with the Contracts module enabled; at least 1 Third party exists. 1. On the left menu, click [New contract or subscription] | D9: 1. New contract screen is displayed (page title = "New contract") | E9: CONTRACT_List_01 | F9: Passed | G9: 46325 | H9: Automated by Selenium IDE (23130094_BuiAnhHau_ASM7.side)
A10: CONTRACT_Create_02 | B10: Check layout and default values of New contract screen | C10: PRE: Signed in the Dolibarr demo with the Contracts module enabled; at least 1 Third party exists. 1. Open New contract screen (CONTRACT_Create_01) 2. Check the displayed fields, default values and buttons | D10: 2. Screen displays: - Third party (required, bold label, empty - "Select a third party") - Sales representative following-up contract (default = David Doe) - Sales representative signing contract (default = David Doe) - Date (default = current date) - Project (empty), Note (public), Note (internal) - Buttons [CREATE DRAFT] and [CANCEL] | E10: CONTRACT_Create_01 | F10: Passed | G10: 46325 | H10: Automated by Selenium IDE (23130094_BuiAnhHau_ASM7.side)
A11: CONTRACT_Create_03 | B11: Check creating a draft contract with only the required field (Third party) | C11: PRE: Signed in the Dolibarr demo with the Contracts module enabled; at least 1 Third party exists. Third party = Testldr1. 1. On New contract screen, select Third party = Testldr1 2. Keep the other fields as default 3. Click [CREATE DRAFT] button | D11: 3. Contract is created, Contract detail screen is displayed - Status = Draft - Ref is a provisional ref (e.g. "(PROV...)") - Third party = Testldr1 | E11: CONTRACT_Create_01 | F11: Passed | G11: 46325 | H11: Automated by Selenium IDE (23130094_BuiAnhHau_ASM7.side)
A12: CONTRACT_Create_04 | B12: Check creating a contract with Note (internal) filled | C12: PRE: Signed in the Dolibarr demo with the Contracts module enabled; at least 1 Third party exists. Third party = Testldr1; Note (internal) = Internal note 01. 1. On New contract screen, select Third party = Testldr1 2. Input Note (internal) = Internal note 01 3. Click [CREATE DRAFT] button 4. On Contract detail screen, open tab [Notes] | D12: 3. Contract is created, Contract detail screen is displayed 4. Tab [Notes] shows the internal note = "Internal note 01" | E12: CONTRACT_Create_01 | F12: Passed | G12: 46325 | H12: Automated by Selenium IDE (23130094_BuiAnhHau_ASM7.side)
A13: CONTRACT_Create_05 | B13: Check required field - Third party | C13: PRE: Signed in the Dolibarr demo with the Contracts module enabled; at least 1 Third party exists. 1. On New contract screen, do not select Third party 2. Click [CREATE DRAFT] button | D13: 2. New contract screen is still displayed - Error message "Field 'Third party' is required" is displayed - No contract is created | E13: CONTRACT_Create_01 | F13: Passed | G13: 46325 | H13: Automated by Selenium IDE (23130094_BuiAnhHau_ASM7.side)
A14: CONTRACT_Create_06 | B14: Check new contract is displayed in the Contracts list after creating | C14: PRE: Signed in the Dolibarr demo with the Contracts module enabled; at least 1 Third party exists. Third party = Testldr1. 1. Create a draft contract (steps of CONTRACT_Create_03) 2. Write down the Ref of the new contract on Contract detail screen 3. Open Contracts list screen 4. Input the Ref into the Ref. filter box and press Enter | D14: 2. The Ref (provisional) is displayed on the detail screen 4. The new contract is displayed in the list | E14: CONTRACT_Create_03 | F14: Passed | G14: 46325 | H14: Automated by Selenium IDE (23130094_BuiAnhHau_ASM7.side)
A15: CONTRACT_Create_07 | B15: Check cancelling create contract | C15: PRE: Signed in the Dolibarr demo with the Contracts module enabled; at least 1 Third party exists. Third party = Testldr1. 1. Open Contracts list screen and write down n in the title "Contracts (n)" 2. Click [New contract or subscription] on the left menu 3. Select Third party = Testldr1 4. Click [CANCEL] button 5. Open Contracts list screen again | D15: 4. New contract screen is closed (back to the previous screen) 5. Page title is still "Contracts (n)" - no contract was created | E15: CONTRACT_List_01 | F15: Passed | G15: 46325 | H15: Automated by Selenium IDE (23130094_BuiAnhHau_ASM7.side)
A16: CONTRACT_Create_08 | B16: Check creating two contracts continuously | C16: PRE: Signed in the Dolibarr demo with the Contracts module enabled; at least 1 Third party exists. Third party = Testldr1 (both contracts). 1. Open Contracts list screen and write down n in the title "Contracts (n)" 2. Create the 1st draft contract (steps of CONTRACT_Create_03) 3. Click [New contract or subscription] again and create the 2nd draft contract 4. Open Contracts list screen | D16: 3. New contract screen is displayed again with empty Third party (no data kept from the previous contract) 4. Page title = "Contracts (n+2)" | E16: CONTRACT_Create_03 | F16: Passed | G16: 46325 | H16: Automated by Selenium IDE (23130094_BuiAnhHau_ASM7.side)
A17: CONTRACT_Create_09 | B17: Check creating a contract with a past Date | C17: PRE: Signed in the Dolibarr demo with the Contracts module enabled; at least 1 Third party exists. Third party = Testldr1; Date = 01/01/2026. 1. On New contract screen, select Third party = Testldr1 2. Clear the Date field and input 01/01/2026 3. Click [CREATE DRAFT] button | D17: 3. Contract is created successfully - Contract date = 01/01/2026 is displayed on Contract detail screen | E17: CONTRACT_Create_01 | F17: Passed | G17: 46325 | H17: Automated by Selenium IDE (23130094_BuiAnhHau_ASM7.side)
A18: CONTRACT_Create_10 | B18: Check Note (internal) with special characters | C18: PRE: Signed in the Dolibarr demo with the Contracts module enabled; at least 1 Third party exists. Third party = Testldr1; Note (internal) = Note @#$%&*(). 1. On New contract screen, select Third party = Testldr1 2. Input Note (internal) = Note @#$%&*() 3. Click [CREATE DRAFT] button 4. On Contract detail screen, open tab [Notes] | D18: 3. Contract is created successfully, no error message 4. Tab [Notes] shows the internal note exactly as input: Note @#$%&*() | E18: CONTRACT_Create_01 | F18: Passed | G18: 46325 | H18: Automated by Selenium IDE (23130094_BuiAnhHau_ASM7.side)
A19: CONTRACT_Create_11 | B19: Check Note (internal) with a very long value (1000 characters) | C19: PRE: Signed in the Dolibarr demo with the Contracts module enabled; at least 1 Third party exists. Third party = Testldr1; Note (internal) = 1000 characters "A". 1. On New contract screen, select Third party = Testldr1 2. Input Note (internal) = 1000 characters "A" 3. Click [CREATE DRAFT] button | D19: 3. System does not show any technical/system error page - Contract is created and Contract detail screen is displayed | E19: CONTRACT_Create_01 | F19: Passed | G19: 46325 | H19: Automated by Selenium IDE (23130094_BuiAnhHau_ASM7.side)
A20: CONTRACT_List_01 | B20: Check displaying Contracts list screen by selecting [Commercial] > [Contracts/Subscriptions] > [List] from the menu | C20: PRE: Signed in the Dolibarr demo with the Contracts module enabled; at least 1 Third party exists. 1. On Dolibarr home page, click menu [Commercial] on the top menu bar 2. Click [List] under [Contracts/Subscriptions] on the left menu | D20: 1. Commerce area is displayed, left menu has [Contracts/Subscriptions] 2. Contracts list screen is displayed - Page title = "Contracts (n)" (n = number of contracts) - Table of contracts is displayed | F20: Passed | G20: 46325 | H20: Automated by Selenium IDE (23130094_BuiAnhHau_ASM7.side)
A21: CONTRACT_List_02 | B21: Check layout of Contracts list screen | C21: PRE: Signed in the Dolibarr demo with the Contracts module enabled; at least 1 Third party exists. 1. Open Contracts list screen (CONTRACT_List_01) 2. Check the columns, the filter row and the icons | D21: 2. Screen displays: - Columns: Ref., Ref. customer, Ref. vendor, Third party, Zip Code, Phone, Mobile, Contract date - Filter row with a search icon (magnifier) and a clear icon (X) - Rows of contracts below | E21: CONTRACT_List_01 | F21: Passed | G21: 46325 | H21: Automated by Selenium IDE (23130094_BuiAnhHau_ASM7.side)
A22: CONTRACT_Search_01 | B22: Check searching contracts by an existing Ref | C22: PRE: Signed in the Dolibarr demo with the Contracts module enabled; at least 1 Third party exists. At least 1 contract exists in the list. 1. On Contracts list screen, take the Ref of the first contract in the list 2. Input that Ref (without parentheses) into the Ref. filter box 3. Press Enter | D22: 3. The contract with that Ref is displayed in the list | E22: CONTRACT_List_01 | F22: Passed | G22: 46325 | H22: Automated by Selenium IDE (23130094_BuiAnhHau_ASM7.side)
A23: CONTRACT_Search_02 | B23: Check searching contracts by a non-existent Ref | C23: PRE: Signed in the Dolibarr demo with the Contracts module enabled; at least 1 Third party exists. 1. On Contracts list screen, input Ref = NOT_EXIST_999 into the Ref. filter box 2. Press Enter | D23: 2. No contract is displayed - Page title = "Contracts (0)" - Message "No record found" is displayed | E23: CONTRACT_List_01 | F23: Passed | G23: 46325 | H23: Automated by Selenium IDE (23130094_BuiAnhHau_ASM7.side)
A24: CONTRACT_Search_03 | B24: Check searching contracts by Third party | C24: PRE: Signed in the Dolibarr demo with the Contracts module enabled; at least 1 Third party exists. A contract of Third party "Testldr1" exists (created by the script). 1. Create a draft contract with Third party = Testldr1 2. On Contracts list screen, input "Testldr1" into the Third party filter box 3. Press Enter | D24: 3. Only contracts whose Third party contains "Testldr1" are displayed in the list (at least 1) | E24: CONTRACT_List_01 | F24: Passed | G24: 46325 | H24: Automated by Selenium IDE (23130094_BuiAnhHau_ASM7.side)
A25: CONTRACT_Search_04 | B25: Check filtering contracts by Status = Draft | C25: PRE: Signed in the Dolibarr demo with the Contracts module enabled; at least 1 Third party exists. At least 1 contract with Status = Draft exists. 1. Create a draft contract with Third party = Testldr1 2. On Contracts list screen, input "PROV" into the Ref. filter box (draft contracts have a provisional Ref) 3. Press Enter | D25: 3. All displayed contracts have a provisional Ref "(PROV...)" = Status Draft (at least 1) | E25: CONTRACT_List_01 | F25: Passed | G25: 46325 | H25: Automated by Selenium IDE (23130094_BuiAnhHau_ASM7.side)
A26: CONTRACT_Search_05 | B26: Check clearing the filter | C26: PRE: Signed in the Dolibarr demo with the Contracts module enabled; at least 1 Third party exists. A filter is applied (e.g. CONTRACT_Search_02). 1. On Contracts list screen with a filter applied, click the clear icon (X) in the filter row | D26: 1. Filter boxes are cleared - The full list of contracts is displayed again | E26: CONTRACT_Search_02 | F26: Passed | G26: 46325 | H26: Automated by Selenium IDE (23130094_BuiAnhHau_ASM7.side)
A27: CONTRACT_Search_06 | B27: Check sorting contracts by Ref (ascending, descending) | C27: PRE: Signed in the Dolibarr demo with the Contracts module enabled; at least 1 Third party exists. At least 2 contracts exist (default sort is Ref ascending). 1. On Contracts list screen, click the column header [Ref.] 2. Click the column header [Ref.] one more time | D27: 1. The order of contracts is reversed (Ref descending) 2. The order of contracts is back to Ref ascending | E27: CONTRACT_List_01 | F27: Passed | G27: 46325 | H27: Automated by Selenium IDE (23130094_BuiAnhHau_ASM7.side)
A28: CONTRACT_Search_07 | B28: Check sorting contracts by Contract date (ascending, descending) | C28: PRE: Signed in the Dolibarr demo with the Contracts module enabled; at least 1 Third party exists. At least 2 contracts with different dates exist. 1. On Contracts list screen, click the column header [Contract date] 2. Click the column header [Contract date] one more time | D28: 1. Contracts are sorted by Contract date in one direction (ascending) 2. Contracts are sorted by Contract date in the opposite direction (descending) | E28: CONTRACT_List_01 | F28: Passed | G28: 46325 | H28: Automated by Selenium IDE (23130094_BuiAnhHau_ASM7.side)
A29: CONTRACT_View_01 | B29: Check viewing Contract detail screen by clicking a contract in the list | C29: PRE: Signed in the Dolibarr demo with the Contracts module enabled; at least 1 Third party exists. At least 1 contract exists in the list. 1. On Contracts list screen, click the Ref of the first contract | D29: 1. Contract detail screen is displayed (tab [Notes] is available) | E29: CONTRACT_List_01 | F29: Passed | G29: 46325 | H29: Automated by Selenium IDE (23130094_BuiAnhHau_ASM7.side)
A30: CONTRACT_View_02 | B30: Check going back to the list from Contract detail screen | C30: PRE: Signed in the Dolibarr demo with the Contracts module enabled; at least 1 Third party exists. Currently on a Contract detail screen. 1. Click [Back to list] link | D30: 1. Contracts list screen is displayed | E30: CONTRACT_View_01 | F30: Passed | G30: 46325 | H30: Automated by Selenium IDE (23130094_BuiAnhHau_ASM7.side)
A31: CONTRACT_Edit_01 | B31: Check modifying Ref. customer of a draft contract | C31: PRE: Signed in the Dolibarr demo with the Contracts module enabled; at least 1 Third party exists. A Draft contract exists (created in CONTRACT_Create_03); new Ref. customer = RC_EDIT_01. 1. Open Contract detail screen of the draft contract 2. Click the edit (pencil) icon next to [Ref. customer] 3. Input Ref. customer = RC_EDIT_01 4. Click the save button next to the input box | D31: 2. Input box of Ref. customer is displayed 4. Ref. customer = RC_EDIT_01 is displayed on Contract detail screen | E31: CONTRACT_Create_03 | F31: Passed | G31: 46325 | H31: Automated by Selenium IDE (23130094_BuiAnhHau_ASM7.side)
A32: CONTRACT_Edit_02 | B32: Check cancelling modify Ref. customer | C32: PRE: Signed in the Dolibarr demo with the Contracts module enabled; at least 1 Third party exists. A Draft contract exists (created in CONTRACT_Create_03). 1. Open Contract detail screen of the draft contract 2. Click the edit (pencil) icon next to [Ref. customer] 3. Input Ref. customer = RC_NOEDIT_01 4. Click the cancel button next to the input box | D32: 4. Input box is closed - Ref. customer is NOT changed (not RC_NOEDIT_01) | E32: CONTRACT_Create_03 | F32: Passed | G32: 46325 | H32: Automated by Selenium IDE (23130094_BuiAnhHau_ASM7.side)
... A34: CONTRACT_Delete_02 | B34: Check cancelling delete contract | C34: PRE: Signed in the Dolibarr demo with the Contracts module enabled; at least 1 Third party exists. A Draft contract exists (created in CONTRACT_Create_03). 1. Open Contract detail screen of the draft contract 2. Click [DELETE] button 3. Click [No] (or close) on the confirmation message | D34: 3. Confirmation message is closed - Contract detail screen is still displayed and the contract still exists | E34: CONTRACT_Create_03 | F34: Passed | G34: 46325 | H34: Automated by Selenium IDE (23130094_BuiAnhHau_ASM7.side)

Sheet Test Report
B1: TEST REPORT
B3: Project Name | C3: =Cover!C4 | E3: Creator | G3: Bui Anh Hau
B4: Project Code | C4: =Cover!C5 | E4: Reviewer/Approver
B5: Document Code | C5: DOLIBARR_Test Report | E5: Issue Date | G5: 46325
B6: Notes
B10: No | C10: Module code | D10: Pass | E10: Fail | F10: Untested | G10: Blocked | H10: Skipped | I10: Number of test cases
B11: 1 | C11: =Contracts!B2 | D11: =Contracts!A6 | E11: =Contracts!B6 | F11: =Contracts!C6 | G11: =Contracts!D6 | H11: =Contracts!E6 | I11: =Contracts!F6
C15: Sub total | D15: =SUM(D11:D14) | E15: =SUM(E11:E14) | F15: =SUM(F11:F14) | G15: =SUM(G11:G14) | H15: =SUM(H11:H14) | I15: =SUM(I11:I14)
C17: Test coverage | E17: =IFERROR((D15+E15)*100/(I15-G15-H15),0) | F17: %
C18: Test successful coverage | E18: =IFERROR(D15*100/(D15+E15),0) | F18: %
