Workbook
Name _Toc301930468: TestDesign!$B$219
Name _Toc301930478: TestDesign!$B$379
Name ACTION: #REF!
Name LOCAL_DATE_SEPARATOR: #REF!
Name LOCAL_DAY_FORMAT: #REF!
Name LOCAL_HOUR_FORMAT: #REF!
Name LOCAL_MINUTE_FORMAT: #REF!
Name LOCAL_MONTH_FORMAT: #REF!
Name LOCAL_SECOND_FORMAT: #REF!
Name LOCAL_TIME_SEPARATOR: #REF!
Name LOCAL_YEAR_FORMAT: #REF!

Sheet Cover
B2: TEST CASE
B4: Project Name | C4: DOLIBARR | F4: Creator | G4: Do Minh Phuoc
B5: Project Code | C5: DOLIBARR | F5: Reviewer/Approver
B6: Document Code | C6: DOLIBARR_TestCase | F6: Issue Date
F7: Version | G7: 0.1
B10: Record of change
B11: Effective Date | C11: Version | D11: Change Item | E11: *A,D,M | F11: Change description | G11: Reference
B12: 20/10/2026 | C12: 0.1 | D12: Products | E12: A | F12: Created 27 Product test cases | G12: Assignment 6
B13: 20/10/2026 | C13: 0.1 | D13: Contracts | E13: A | F13: Created 26 Contract test cases | G13: Assignment 6
B14: 20/10/2026 | C14: 0.1 | D14: Project/Task | E14: A | F14: Create 26 Project and Task test cases | G14: Assignment 6
B15: 20/10/2026 | C15: 0.1 | D15: Commercial Proposals | E15: A | F15: Created 29 Commercial Proposal test cases | G15: Assignment 6
B16: 20/10/2026 | C16: 0.1 | D16: Contacts/Addresses | E16: A | F16: Created 30 Contact/Address test cases | G16: Assignment 6

Sheet Test case List
D1: TEST CASE LIST
B3: Project Name | D3: =Cover!C4 -> DOLIBARR
B4: Project Code | D4: =Cover!C5 -> DOLIBARR
B5: Test Environment Setup Description | D5: Dolibarr ERP & CRM demo 24.0.2; Google Chrome; authorized Products module access.
B8: No | C8: Function Name | D8: Sheet Name | E8: Description | F8: Pre-Condition
B9: 1 | C9: Add Product | D9: Add Product | E9: Create a product and validate required fields. | F9: Sign in and access Products; use independent sample references.
B10: 2 | C10: List / Search Product | D10: List Product | E10: List, find, view, and verify saved products. | F10: Sign in and prepare test records when necessary.
B11: 3 | C11: Edit Product | D11: Edit Product | E11: Update product data and verify saved changes. | F11: Sign in and prepare an editable test product.
B12: 4 | C12: Delete Product | D12: Delete Product | E12: Check deletion and cancel behavior using owned test data. | F12: Sign in and prepare disposable, tester-owned products.
B13: 5 | C13: Contracts | D13: Contracts | E13: Create, list/search/sort, view, edit and delete (draft) contracts. | F13: Sign in; at least 1 Third party exists; the contract list has sample data.
B14: 6 | C14: Commercial Proposals | D14: Commercial Proposals | E14: Create a draft proposal, add lines, change status (validate, sign, refuse, cancel, clone) and list/filter proposals. | F14: Sign in with Commercial > Proposals access; third party ‘AAA Company’ exists; test records tagged QA23130284.
B15: 7 | C15: Add Contact/Address | D15: Add Contact | E15: Create a contact/address and validate required fields, email format, length limits and third-party link. | F15: Sign in and open Third parties > Contacts/Addresses; use independent sample names.
B16: 8 | C16: List / Search Contact | D16: List Contact | E16: List, search (name, email), view and verify saved contacts. | F16: Sign in and prepare test contacts when necessary.
B17: 9 | C17: Edit Contact/Address | D17: Edit Contact | E17: Update contact data, third-party link and status; verify validation on edit. | F17: Sign in and prepare an editable test contact.
B18: 10 | C18: Delete Contact/Address | D18: Delete Contact | E18: Check deletion confirmation, cancel, single and mass deletion using owned test data. | F18: Sign in and prepare disposable, tester-owned contacts.
B19: 11 | C19: Create New Project/Lead | D19: Tasks_Management | E19: Verify the functionality of creating a new project, saving customer information, Lead status, and view permissions | F19: Logged into the Dolibarr system with an account having Project Manager permissions
B20: 12 | C20: Approve project | D20: Tasks_Management | E20: Verify project approval from Draft status to Valid status to allow Task creation; when a project is open, it defaults to valid status | F20: Project has been created in Draft status
... B24: 16 | C24: Close / Change Task status | D24: Tasks_Management | E24: Verify changing Task status to Closed or Reopened | F24: Task is currently in Active status

Sheet TestDesign
A1: Requirement Level 1 | B1: Requirement Level 2 | C1: Requirement Level 3 | D1: Test Criteria | E1: Test Type | F1: Note
A2: 1. Products | B2: 1.1 Create | C2: Successful create / Minimum data | D2: Check create a product using mandatory fields only. | E2: Function
C3: Successful create / Optional text | D3: Check create with description, note and public URL. | E3: Function
C4: Required field / Product ref. | D4: Check reject creation when Product ref. is empty. | E4: Function
C5: Required field / Label | D5: Check reject creation when Label is empty. | E5: Function
C6: Required fields / Both empty | D6: Check prevent creation when both required fields are empty. | E6: Function
C7: Validation recovery | D7: Check correct a missing required field after validation. | E7: Function
C8: Sell status option | D8: Check create a product with an alternative Sell status. | E8: Function
C9: Purchase status option | D9: Check create a product with an alternative Purchase status. | E9: Function
C10: Valid monetary fields | D10: Check create a product with a positive selling price. | E10: Function
C11: Invalid monetary input | D11: Check do not store alphabetic text as a numeric selling price. | E11: Function
C12: Cancel creation | D12: Check cancel a filled New product form without saving. | E12: Function
B13: 1.2 Read | C13: List display | D13: Check open Products list and verify core columns. | E13: GUI
C14: Search by reference | D14: Check find a prepared product using its exact Product ref.. | E14: Function
C15: Search by label | D15: Check filter Products using a prepared label. | E15: Function
C16: Search / No match | D16: Check return no unrelated records for an unmatched reference. | E16: Function
C17: Details / Persistence | D17: Check verify saved product details after page reload. | E17: Function
B18: 1.3 Update | C18: Open edit form | D18: Check open MODIFY for an existing product. | E18: GUI
C19: Update Label | D19: Check save a changed product Label and verify persistence. | E19: Function
C20: Update Description | D20: Check edit product Description without altering reference. | E20: Function
C21: Update Selling price | D21: Check update selling price to a valid positive value. | E21: Function
C22: Update Sell status | D22: Check change Sell status of an existing product. | E22: Function
C23: Required Label on edit | D23: Check reject clearing required Label during an update. | E23: Function
C24: Cancel edit | D24: Check cancel changes in product edit form. | E24: Function
B25: 1.4 Delete | C25: Delete action / Confirmation | D25: Check check deletion requires an explicit confirmation step. | E25: GUI
C26: Cancel deletion | D26: Check cancel the delete operation and preserve the product. | E26: Function
C27: Delete successful / Unlinked data | D27: Check delete one disposable product and verify removal. | E27: Function
C28: Delete isolation / Other product | D28: Check deleting one product does not remove a separate product. | E28: Function
A29: 2. Third Parties | B29: 2.1 Create | C29: Create / Minimum required information | D29: Check create a Third Party with required name and one selected role. | E29: Function
C30: Create / Optional details | D30: Check create a Third Party with optional address and contact fields completed. | E30: Function
C31: Required field / Third-party name | D31: Check prevent creation when Third-party name is empty. | E31: Function
C32: Name / Whitespace input | D32: Check how the form validates a whitespace-only Third-party name. | E32: Function
C33: New Prospect shortcut | D33: Check the New Prospect form preselects and saves the Prospect role. | E33: Function
C34: New Customer shortcut | D34: Check the New Customer form retains Customer classification after creation. | E34: Function
C35: New Vendor shortcut | D35: Check the New Vendor form retains Vendor classification after creation. | E35: Function
C36: Business roles / Multiple selection | D36: Check create a Third Party with supported role combinations. | E36: Function
C37: Customer / Vendor codes | D37: Check saved Customer Code or Vendor Code matches the selected role. | E37: Function
C38: Email / Invalid format | D38: Check the form response to a malformed email value when an email is provided. | E38: Function
C39: Cancel creation | D39: Check cancelling a completed New Third Party form does not save a record. | E39: Function
B40: 2.2 Read | C40: Third Party list / Display | D40: Check Third Parties list opens with available records and columns. | E40: GUI
...

Sheet Product
A2: Module Code | B2: CRUD_PRODUCT | J2: Passed
A3: Test requirement | B3: CRUD Product | J3: Failed
A4: Tester | B4: Do Minh Phuoc | J4: Blocked
A5: Passed | B5: Failed | C5: Untested | D5: Blocked | E5: Skipped | F5: Number of Test cases | J5: Untested
A6: =COUNTIF(F9:F996,"Passed") -> 0 | B6: =COUNTIF(F9:F996,"Failed") -> 0 | C6: =F6-E6-D6-B6-A6 -> 27 | D6: =COUNTIF(F9:F996,"Blocked") -> 0 | E6: =COUNTIF(F9:F996,"Skipped") -> 0 | F6: =COUNTA(A9:A996) -> 27 | J6: Skipped
A8: ID | B8: Test Case Description | C8: Test Case Procedure | D8: Expected Output | E8: Inter-test case Dependence | F8: Result | G8: Test date | H8: Note
A9: ADD_PRODUCT-01 | B9: Create a product using mandatory fields only | C9: PRE: Signed in with Products access; reference QA23130250-C01-[RUN] does not exist. 1. Open Products > New product. 2. Enter Product ref. = QA23130250-C01-[RUN]; Label = Test Basic Product 01. 3. Keep optional fields blank and leave visible defaults unchanged. 4. Click CREATE; open the saved product details. | D9: Product is created and its detail page shows the exact reference and label entered; no optional field input is required. | F9: Untested
A10: ADD_PRODUCT-02 | B10: Create with description, note and public URL | C10: PRE: New unique reference QA23130250-C02-[RUN]. 1. Open New product. 2. Enter Product ref. = QA23130250-C02-[RUN], Label = Test Text Product. 3. Enter Description = Product created for QA review; Public URL = https://example.com/qa-product; Note = Internal QA note. 4. Click CREATE, then review detail fields. | D10: Creation succeeds; entered optional text and URL are retained in their corresponding product fields (including the Notes area when applicable). | F10: Untested
A11: ADD_PRODUCT-03 | B11: Reject creation when Product ref. is empty | C11: PRE: On New product form. 1. Leave Product ref. blank. 2. Enter Label = Missing Reference Test. 3. Click CREATE. 4. Check the form response and whether any product was created. | D11: Creation is prevented and Product ref. is identified as required; no product with this attempted data is added. | F11: Untested
A12: ADD_PRODUCT-04 | B12: Reject creation when Label is empty | C12: PRE: New unique reference QA23130250-C04-[RUN]. 1. Enter Product ref. = QA23130250-C04-[RUN]. 2. Leave Label empty. 3. Click CREATE. 4. Check the response and product list. | D12: Creation is prevented; Label is identified as required and the reference is not added as a new product. | F12: Untested
A13: ADD_PRODUCT-05 | B13: Prevent creation when both required fields are empty | C13: PRE: On New product form. 1. Leave Product ref. and Label empty. 2. Click CREATE. 3. Observe validation and stay on the form. | D13: No product is created; the form requires missing mandatory input. Exact message text is not assumed. | F13: Untested
A14: ADD_PRODUCT-06 | B14: Correct a missing required field after validation | C14: PRE: New unique reference QA23130250-C06-[RUN]. 1. Open New product; fill Product ref. = QA23130250-C06-[RUN]; leave Label empty. 2. Click CREATE and observe required-field validation. 3. Enter Label = Corrected After Error. 4. Click CREATE again; inspect created details. | D14: First attempt is blocked; after entering the missing Label, one product is created with the corrected reference and label. | F14: Untested
A15: ADD_PRODUC T_07 | B15: Create a product with an alternative Sell status | C15: PRE: New unique reference QA23130250-C07-[RUN]; Sell status has an alternative in the form. 1. Open New product. 2. Fill Product ref. = QA23130250-C07-[RUN], Label = Alternate Sell Status. 3. In Status (Sell), choose an available option different from For sale; keep Purchase at default. 4. Click CREATE; check status in product details/list. | D15: Product is created; Sell status matches the option selected and Purchase status retains the default value. | F15: Untested
A16: ADD_PRODUC T_08 | B16: Create a product with an alternative Purchase status | C16: PRE: New unique reference QA23130250-C08-[RUN]; Purchase status has an alternative. 1. Open New product; fill reference QA23130250-C08-[RUN] and Label = Alternate Purchase Status. 2. Keep Sell at default. 3. Change Status (Purchase) to an available alternative to For purchase. 4. Click CREATE; inspect the saved statuses. | D16: Product is created; Purchase status equals the selected value and Sell status keeps its original default. | F16: Untested
A17: ADD_PRODUC T_09 | B17: Create a product with a positive selling price | C17: PRE: New reference QA23130250-C09-[RUN]. 1. Open New product; enter ref QA23130250-C09-[RUN], Label = Priced Test Product. 2. Enter Selling price = 125.50; retain shown tax mode and Tax Rate = 20% where available. 3. Click CREATE; visit Selling prices or details. | D17: Product is created; selling price is recorded as 125.50 in the configured tax mode; tax selection remains as chosen. | F17: Untested
A18: ADD_PRODUC T_10 | B18: Do not store alphabetic text as a numeric selling price | C18: PRE: New reference QA23130250-C10-[RUN]. 1. Open New product; fill required fields with QA23130250-C10-[RUN] and Label = Invalid Price Input. 2. Try typing Selling price = abc. 3. Observe field behavior and attempt CREATE only if the form allows it. 4. Inspect any saved price or validation. | D18: Non-numeric text is not persisted as a numeric selling price. Input may be rejected/cleared by the field or validation may be shown; the exact UI response must be observed. | F18: Untested
A19: ADD_PRODUC T_11 | B19: Cancel a filled New product form without saving | C19: PRE: New reference QA23130250-C11-[RUN]. 1. Open New product. 2. Enter Product ref. = QA23130250-C11-[RUN]; Label = Cancel Creation Test. 3. Click CANCEL. 4. Return to Products > List and search for the reference. | D19: The create operation is abandoned; no new product with the test reference exists in the list. | F19: Untested
A20: LIST_PRODUCT-01 | B20: Open Products list and verify core columns | C20: PRE: Signed in and Products module enabled. 1. Click Products > List. 2. Observe the list header and visible rows. 3. Check Product ref., Label, Selling price, Status (Sell) and Status (Purchase) columns. | D20: Products list opens without an error and displays the core columns and product records available to the signed-in account. | F20: Untested
A21: LIST_PRODUCT-02 | B21: Find a prepared product using its exact Product ref. | C21: PRE: Own test product with ref QA23130250-R02-[RUN] and Label = Search By Reference exists. 1. Open Products > List. 2. Enter QA23130250-R02-[RUN] into the Product ref. filter. 3. Run the list search/filter. 4. Open the matching result. | D21: The search result includes the prepared product with the matching exact reference; its detail page opens with the correct ref and label. | E21: Fixture prepared before execution | F21: Untested
A22: LIST_PRODUCT-03 | B22: Filter Products using a prepared label | C22: PRE: Own product QA23130250-R03-[RUN] with Label = Searchable QA Label exists. 1. Open Products > List. 2. Enter Searchable QA Label in the Label filter. 3. Trigger filtering and review the returned rows. | D22: The prepared product appears among the matching results; the product reference links to its correct details. | E22: Fixture prepared before execution | F22: Untested
A23: LIST_PRODUCT-04 | B23: Return no unrelated records for an unmatched reference | C23: PRE: Reference QA23130250-NEVER-[RUN] does not exist. 1. Open Products > List. 2. Filter Product ref. by QA23130250-NEVER-[RUN]. 3. Execute search; inspect the result area. | D23: No product row with an unrelated reference is returned for the exact unmatched filter; the screen remains usable. | F23: Untested
A24: LIST_PRODUCT-05 | B24: Verify saved product details after page reload | C24: PRE: Own product QA23130250-R05-[RUN] exists with Label = Persisted Label; Description = Persisted QA Description. 1. Find and open the product. 2. Check ref, label, description and visible status values. 3. Reload the browser page; check the same values again. | D24: Details show the previously saved values both before and after page reload; no data changes without an edit action. | E24: Fixture prepared before execution | F24: Untested
A25: EDIT_PRODUCT-01 | B25: Open MODIFY for an existing product | C25: PRE: Own product QA23130250-U01-[RUN] exists. 1. Locate it in Products > List. 2. Open product details. 3. Click MODIFY; inspect the edit form and its initial values. | D25: The edit form opens for the selected product and prepopulates its stored data; no changes are saved merely by opening it. | E25: Fixture prepared before execution | F25: Untested
A26: EDIT_PRODUCT-02 | B26: Save a changed product Label and verify persistence | C26: PRE: Own product QA23130250-U02-[RUN] exists, Label = Before Update. 1. Open details > MODIFY. 2. Change Label to After Update 23130250. 3. Save using the edit form action. 4. Reload details and search the list by reference. | D26: The updated Label is displayed in details and list after reload; original Product ref. remains unchanged. | E26: Fixture prepared before execution | F26: Untested
A27: EDIT_PRODUCT-03 | B27: Edit product Description without altering reference | C27: PRE: Own product QA23130250-U03-[RUN] exists with Description = Old QA Description. 1. Open MODIFY. 2. Replace Description with New QA Description 23130250. 3. Save; reopen details and reload. | D27: New description is persisted and displayed; Product ref. and Label are unchanged. | E27: Fixture prepared before execution | F27: Untested
A28: EDIT_PRODUCT-04 | B28: Update selling price to a valid positive value | C28: PRE: Own product QA23130250-U04-[RUN] exists with Selling price = 100.00 under the current tax mode. 1. Open product > MODIFY (or relevant Selling prices edit control). 2. Change Selling price to 149.50 without changing tax mode. 3. Save and revisit pricing. | D28: The saved selling price is 149.50 in the same tax mode; reference, label and other unrelated fields remain intact. | E28: Fixture prepared before execution | F28: Untested
A29: EDIT_PRODUCT-05 | B29: Change Sell status of an existing product | C29: PRE: Own product QA23130250-U05-[RUN] exists with Status (Sell) = For sale; an alternative is available. 1. Open product > MODIFY. 2. Change Status (Sell) to a different available value. 3. Save; check the badge in details/list. | D29: Selected Sell status is persisted and shown correctly; Purchase status does not change unexpectedly. | E29: Fixture prepared before execution | F29: Untested
A30: EDIT_PRODUCT-06 | B30: Reject clearing required Label during an update | C30: PRE: Own product QA23130250-U06-[RUN] exists with Label = Keep This Label. 1. Open MODIFY. 2. Clear Label completely. 3. Save; observe validation. 4. Reload details and verify original label. | D30: An empty required Label is not saved; the previously stored valid Label remains unchanged. | E30: Fixture prepared before execution | F30: Untested
A31: EDIT_PRODU CT_07 | B31: Cancel changes in product edit form | C31: PRE: Own product QA23130250-U07-[RUN] exists with Label = Original Label U07. 1. Open MODIFY. 2. Change Label to Should Not Save U07. 3. Click CANCEL (if edit form offers it) or navigate back without saving. 4. Reload details. | D31: The unsaved change is discarded; Label remains Original Label U07 after reload. | E31: Fixture prepared before execution | F31: Untested
A32: DELETE_PRODUCT-01 | B32: Check deletion requires an explicit confirmation step | C32: PRE: Own disposable product QA23130250-D01-[RUN] exists and has no known linked records. 1. Open its detail page. 2. Click DELETE. 3. Examine the confirmation screen/dialog without accepting deletion. | D32: A clear confirmation action is available before deletion; the product still exists until confirmation. Confirm actual behavior on the demo. | E32: Fixture prepared before execution | F32: Untested
A33: DELETE_PRODUCT-02 | B33: Cancel the delete operation and preserve the product | C33: PRE: Own product QA23130250-D02-[RUN] exists. 1. Open its details and click DELETE. 2. Choose No/Cancel on the deletion confirmation (if offered). 3. Return to Products > List; search by reference. | D33: Deletion is not carried out; the product remains searchable and its details are unchanged. | E33: Fixture prepared before execution | F33: Untested
A34: DELETE_PRODUCT-03 | B34: Delete one disposable product and verify removal | C34: PRE: Own disposable unlinked product QA23130250-D03-[RUN] exists; deletion permission verified. 1. Open product details. 2. Click DELETE and confirm the operation using the provided control. 3. Return to Products > List; search exact Product ref. | D34: Deletion completes according to the UI; the product no longer appears in exact-reference search. | E34: Fixture prepared before execution; own disposable data | F34: Untested
A35: DELETE_PRODUCT-04 | B35: Deleting one product does not remove a separate product | C35: PRE: Two independent disposable products exist: QA23130250-D04A-[RUN] and QA23130250-D04B-[RUN]. 1. Open D04A details and execute confirmed DELETE. 2. Search exact reference D04A, then search exact reference D04B. 3. Open D04B details. | D35: Deleted D04A is absent; independently created D04B still exists with its original data intact. | E35: Two own disposable fixtures prepared | F35: Untested

Sheet Contract
A2: Module Code | B2: CONTRACT | J2: Passed
A3: Test requirement | B3: Contracts | J3: Failed
A4: Tester | B4: Bui Anh Hau | J4: Blocked
A5: Passed | B5: Failed | C5: Untested | D5: Blocked | E5: Skipped | F5: Number of Test cases | J5: Untested
A6: =COUNTIF(F9:F996,"Passed") -> 0 | B6: =COUNTIF(F9:F996,"Failed") -> 0 | C6: =F6-E6-D6-B6-A6 -> 26 | D6: =COUNTIF(F9:F996,"Blocked") -> 0 | E6: =COUNTIF(F9:F996,"Skipped") -> 0 | F6: =COUNTA(A9:A996) -> 26 | J6: Skipped
A8: ID | B8: Test Case Description | C8: Test Case Procedure | D8: Expected Output | E8: Inter-test case Dependence | F8: Result | G8: Test date | H8: Note
A9: CONTRACT_Create_01 | B9: Check displaying New contract screen by clicking [New contract or subscription] on the left menu | C9: PRE: Signed in the Dolibarr demo with the Contracts module enabled; at least 1 Third party exists. 1. On the left menu, click [New contract or subscription] | D9: 1. New contract screen is displayed (page title = "New contract") | E9: CONTRACT_List_01
A10: CONTRACT_Create_02 | B10: Check layout and default values of New contract screen | C10: PRE: Signed in the Dolibarr demo with the Contracts module enabled; at least 1 Third party exists. 1. Open New contract screen (CONTRACT_Create_01) 2. Check the displayed fields, default values and buttons | D10: 2. Screen displays: - Third party (required, bold label, empty - "Select a third party") - Sales representative following-up contract (default = David Doe) - Sales representative signing contract (default = David Doe) - Date (default = current date) - Project (empty), Note (public), Note (internal) - Buttons [CREATE DRAFT] and [CANCEL] | E10: CONTRACT_Create_01
A11: CONTRACT_Create_03 | B11: Check creating a draft contract with only the required field (Third party) | C11: PRE: Signed in the Dolibarr demo with the Contracts module enabled; at least 1 Third party exists. Third party = Testldr1. 1. On New contract screen, select Third party = Testldr1 2. Keep the other fields as default 3. Click [CREATE DRAFT] button | D11: 3. Contract is created, Contract detail screen is displayed - Status = Draft - Ref is a provisional ref (e.g. "(PROV...)") - Third party = Testldr1 | E11: CONTRACT_Create_01
A12: CONTRACT_Create_04 | B12: Check creating a contract with Note (internal) filled | C12: PRE: Signed in the Dolibarr demo with the Contracts module enabled; at least 1 Third party exists. Third party = Testldr1; Note (internal) = Internal note 01. 1. On New contract screen, select Third party = Testldr1 2. Input Note (internal) = Internal note 01 3. Click [CREATE DRAFT] button 4. On Contract detail screen, open tab [Notes] | D12: 3. Contract is created, Contract detail screen is displayed 4. Tab [Notes] shows the internal note = "Internal note 01" | E12: CONTRACT_Create_01
A13: CONTRACT_Create_05 | B13: Check required field - Third party | C13: PRE: Signed in the Dolibarr demo with the Contracts module enabled; at least 1 Third party exists. 1. On New contract screen, do not select Third party 2. Click [CREATE DRAFT] button | D13: 2. New contract screen is still displayed - Error message "Field 'Third party' is required" is displayed - No contract is created | E13: CONTRACT_Create_01
A14: CONTRACT_Create_06 | B14: Check new contract is displayed in the Contracts list after creating | C14: PRE: Signed in the Dolibarr demo with the Contracts module enabled; at least 1 Third party exists. Third party = Testldr1. 1. Create a draft contract (steps of CONTRACT_Create_03) 2. Write down the Ref of the new contract on Contract detail screen 3. Open Contracts list screen 4. Input the Ref into the Ref. filter box and press Enter | D14: 2. The Ref (provisional) is displayed on the detail screen 4. The new contract is displayed in the list | E14: CONTRACT_Create_03
A15: CONTRACT_Create_07 | B15: Check cancelling create contract | C15: PRE: Signed in the Dolibarr demo with the Contracts module enabled; at least 1 Third party exists. Third party = Testldr1. 1. Open Contracts list screen and write down n in the title "Contracts (n)" 2. Click [New contract or subscription] on the left menu 3. Select Third party = Testldr1 4. Click [CANCEL] button 5. Open Contracts list screen again | D15: 4. New contract screen is closed (back to the previous screen) 5. Page title is still "Contracts (n)" - no contract was created | E15: CONTRACT_List_01
A16: CONTRACT_Create_08 | B16: Check creating two contracts continuously | C16: PRE: Signed in the Dolibarr demo with the Contracts module enabled; at least 1 Third party exists. Third party = Testldr1 (both contracts). 1. Open Contracts list screen and write down n in the title "Contracts (n)" 2. Create the 1st draft contract (steps of CONTRACT_Create_03) 3. Click [New contract or subscription] again and create the 2nd draft contract 4. Open Contracts list screen | D16: 3. New contract screen is displayed again with empty Third party (no data kept from the previous contract) 4. Page title = "Contracts (n+2)" | E16: CONTRACT_Create_03
A17: CONTRACT_Create_09 | B17: Check creating a contract with a past Date | C17: PRE: Signed in the Dolibarr demo with the Contracts module enabled; at least 1 Third party exists. Third party = Testldr1; Date = 01/01/2026. 1. On New contract screen, select Third party = Testldr1 2. Clear the Date field and input 01/01/2026 3. Click [CREATE DRAFT] button | D17: 3. Contract is created successfully - Contract date = 01/01/2026 is displayed on Contract detail screen | E17: CONTRACT_Create_01
A18: CONTRACT_Create_10 | B18: Check Note (internal) with special characters | C18: PRE: Signed in the Dolibarr demo with the Contracts module enabled; at least 1 Third party exists. Third party = Testldr1; Note (internal) = Note @#$%&*(). 1. On New contract screen, select Third party = Testldr1 2. Input Note (internal) = Note @#$%&*() 3. Click [CREATE DRAFT] button 4. On Contract detail screen, open tab [Notes] | D18: 3. Contract is created successfully, no error message 4. Tab [Notes] shows the internal note exactly as input: Note @#$%&*() | E18: CONTRACT_Create_01
A19: CONTRACT_Create_11 | B19: Check Note (internal) with a very long value (1000 characters) | C19: PRE: Signed in the Dolibarr demo with the Contracts module enabled; at least 1 Third party exists. Third party = Testldr1; Note (internal) = 1000 characters "A". 1. On New contract screen, select Third party = Testldr1 2. Input Note (internal) = 1000 characters "A" 3. Click [CREATE DRAFT] button | D19: 3. System does not show any technical/system error page - Contract is created and Contract detail screen is displayed | E19: CONTRACT_Create_01
A20: CONTRACT_List_01 | B20: Check displaying Contracts list screen by selecting [Commercial] > [Contracts/Subscriptions] > [List] from the menu | C20: PRE: Signed in the Dolibarr demo with the Contracts module enabled; at least 1 Third party exists. 1. On Dolibarr home page, click menu [Commercial] on the top menu bar 2. Click [List] under [Contracts/Subscriptions] on the left menu | D20: 1. Commerce area is displayed, left menu has [Contracts/Subscriptions] 2. Contracts list screen is displayed - Page title = "Contracts (n)" (n = number of contracts) - Table of contracts is displayed
A21: CONTRACT_List_02 | B21: Check layout of Contracts list screen | C21: PRE: Signed in the Dolibarr demo with the Contracts module enabled; at least 1 Third party exists. 1. Open Contracts list screen (CONTRACT_List_01) 2. Check the columns, the filter row and the icons | D21: 2. Screen displays: - Columns: Ref., Ref. customer, Ref. vendor, Third party, Zip Code, Phone, Mobile, Contract date - Filter row with a search icon (magnifier) and a clear icon (X) - Rows of contracts below | E21: CONTRACT_List_01
A22: CONTRACT_Search_01 | B22: Check searching contracts by an existing Ref | C22: PRE: Signed in the Dolibarr demo with the Contracts module enabled; at least 1 Third party exists. Contract CT2610-0007 exists (demo sample data). 1. On Contracts list screen, input Ref = CT2610-0007 into the Ref. filter box 2. Press Enter | D22: 2. Only the contract CT2610-0007 is displayed in the list - Page title = "Contracts (1)" | E22: CONTRACT_List_01
A23: CONTRACT_Search_02 | B23: Check searching contracts by a non-existent Ref | C23: PRE: Signed in the Dolibarr demo with the Contracts module enabled; at least 1 Third party exists. 1. On Contracts list screen, input Ref = NOT_EXIST_999 into the Ref. filter box 2. Press Enter | D23: 2. No contract is displayed - Page title = "Contracts (0)" - Message "No record found" is displayed | E23: CONTRACT_List_01
A24: CONTRACT_Search_03 | B24: Check searching contracts by Third party | C24: PRE: Signed in the Dolibarr demo with the Contracts module enabled; at least 1 Third party exists. A contract of Third party "Generic customer" exists (demo sample data). 1. On Contracts list screen, input "Generic" into the Third party filter box 2. Press Enter | D24: 2. Only contracts whose Third party contains "Generic" are displayed in the list | E24: CONTRACT_List_01
A25: CONTRACT_Search_04 | B25: Check filtering contracts by Status = Draft | C25: PRE: Signed in the Dolibarr demo with the Contracts module enabled; at least 1 Third party exists. At least 1 contract with Status = Draft exists. 1. On Contracts list screen, scroll right to the Status filter 2. Select Status = Draft in the Status filter 3. Press Enter (or click the search icon) | D25: 3. All displayed contracts have Status = Draft | E25: CONTRACT_List_01
A26: CONTRACT_Search_05 | B26: Check clearing the filter | C26: PRE: Signed in the Dolibarr demo with the Contracts module enabled; at least 1 Third party exists. A filter is applied (e.g. CONTRACT_Search_02). 1. On Contracts list screen with a filter applied, click the clear icon (X) in the filter row | D26: 1. Filter boxes are cleared - The full list of contracts is displayed again | E26: CONTRACT_Search_02
A27: CONTRACT_Search_06 | B27: Check sorting contracts by Ref (ascending, descending) | C27: PRE: Signed in the Dolibarr demo with the Contracts module enabled; at least 1 Third party exists. At least 2 contracts exist (default sort is Ref ascending). 1. On Contracts list screen, click the column header [Ref.] 2. Click the column header [Ref.] one more time | D27: 1. The order of contracts is reversed (Ref descending) 2. The order of contracts is back to Ref ascending | E27: CONTRACT_List_01
A28: CONTRACT_Search_07 | B28: Check sorting contracts by Contract date (ascending, descending) | C28: PRE: Signed in the Dolibarr demo with the Contracts module enabled; at least 1 Third party exists. At least 2 contracts with different dates exist. 1. On Contracts list screen, click the column header [Contract date] 2. Click the column header [Contract date] one more time | D28: 1. Contracts are sorted by Contract date in one direction (ascending) 2. Contracts are sorted by Contract date in the opposite direction (descending) | E28: CONTRACT_List_01
A29: CONTRACT_View_01 | B29: Check viewing Contract detail screen by clicking a contract in the list | C29: PRE: Signed in the Dolibarr demo with the Contracts module enabled; at least 1 Third party exists. Contract CT2610-0007 exists in the list (demo sample data). 1. On Contracts list screen, click the Ref "CT2610-0007" | D29: 1. Contract detail screen of CT2610-0007 is displayed - Ref = CT2610-0007 - Third party is the same as in the list | E29: CONTRACT_List_01
A30: CONTRACT_View_02 | B30: Check going back to the list from Contract detail screen | C30: PRE: Signed in the Dolibarr demo with the Contracts module enabled; at least 1 Third party exists. Currently on a Contract detail screen. 1. Click [Back to list] link | D30: 1. Contracts list screen is displayed | E30: CONTRACT_View_01
A31: CONTRACT_Edit_01 | B31: Check modifying Ref. customer of a draft contract | C31: PRE: Signed in the Dolibarr demo with the Contracts module enabled; at least 1 Third party exists. A Draft contract exists (created in CONTRACT_Create_03); new Ref. customer = RC_EDIT_01. 1. Open Contract detail screen of the draft contract 2. Click the edit (pencil) icon next to [Ref. customer] 3. Input Ref. customer = RC_EDIT_01 4. Click the save button next to the input box | D31: 2. Input box of Ref. customer is displayed 4. Ref. customer = RC_EDIT_01 is displayed on Contract detail screen | E31: CONTRACT_Create_03
A32: CONTRACT_Edit_02 | B32: Check cancelling modify Ref. customer | C32: PRE: Signed in the Dolibarr demo with the Contracts module enabled; at least 1 Third party exists. A Draft contract exists (created in CONTRACT_Create_03). 1. Open Contract detail screen of the draft contract 2. Click the edit (pencil) icon next to [Ref. customer] 3. Input Ref. customer = RC_NOEDIT_01 4. Click the cancel button next to the input box | D32: 4. Input box is closed - Ref. customer is NOT changed (not RC_NOEDIT_01) | E32: CONTRACT_Create_03
... A34: CONTRACT_Delete_02 | B34: Check cancelling delete contract | C34: PRE: Signed in the Dolibarr demo with the Contracts module enabled; at least 1 Third party exists. A Draft contract exists (created in CONTRACT_Create_03). 1. Open Contract detail screen of the draft contract 2. Click [DELETE] button 3. Click [No] (or close) on the confirmation message | D34: 3. Confirmation message is closed - Contract detail screen is still displayed and the contract still exists | E34: CONTRACT_Create_03

Sheet Commercial Proposals
A2: Module Code | B2: COMMERCIAL_PROPOSAL
A3: Test requirement | B3: Commercial Proposals
A4: Tester | B4: Nguyen Thanh Tai
A5: Passed | B5: Failed | C5: Untested | D5: Blocked | E5: Skipped | F5: Number of Test cases
A6: 0 | B6: 0 | C6: 29 | D6: 0 | E6: 0 | F6: 29
A9: ID | B9: Test Case Description | C9: Test Case Procedure | D9: Expected Output | E9: Inter-test case Dependence | F9: Result | G9: Test date | H9: Note
A10: ADD_PROPOSAL-01 | B10: Check default values of the New commercial proposal form | C10: PRE: Logged in to demo.dolibarr.org (user David Doe). 1. Open Commercial > Proposals > New proposal. 2. Observe the form without entering anything. | D10: Form 'New commercial proposal' is displayed. Customer is empty ('Select a third party'); Date = today; Validity duration = 15 days; Payment terms, Payment method, Project, Incoterms are empty. Customer, Date and Validity duration are shown as mandatory; buttons [Create draft] and [Cancel] are available.
A11: ADD_PROPOSAL-02 | B11: Create a draft proposal using mandatory fields only | C11: PRE: Logged in to demo.dolibarr.org (user David Doe); third party 'AAA Company' exists. 1. Open New proposal. 2. Select Customer = AAA Company. 3. Keep Date and Validity duration = 15 as default. 4. Enter Note (internal) = QA23130284-C02-[RUN]. 5. Click [Create draft]. | D11: Proposal card opens with a temporary reference (PROVnnn). Status = 'Draft (needs to be validated)'; Customer = AAA Company; Validity ending date = Date + 15 days; all amounts = 0.00. | E11: ADD_PROPOSAL-01
A12: ADD_PROPOSAL-03 | B12: Reject creation when Customer is empty | C12: PRE: On the New proposal form. 1. Leave Customer empty. 2. Keep other fields at default. 3. Click [Create draft]. | D12: Message "Field 'Customer' is required" is displayed; the form stays open with the entered values kept; no proposal is created. | E12: ADD_PROPOSAL-01
A13: ADD_PROPOSAL-04 | B13: Reject Validity duration = non-numeric text | C13: PRE: On the New proposal form with Customer = AAA Company. 1. Enter Validity duration = abc. 2. Click [Create draft]. 3. Check the message and the proposals list count. | D13: An error is displayed ("Field 'Validity duration' is required"); no proposal is created. | E13: ADD_PROPOSAL-01
A14: ADD_PROPOSAL-05 | B14: Check Validity duration = 0 (lower boundary) | C14: PRE: On the New proposal form with Customer = AAA Company. 1. Enter Validity duration = 0. 2. Click [Create draft]. | D14: An error is displayed ("Field 'Validity duration' is required"); no proposal is created. | E14: ADD_PROPOSAL-01
A15: ADD_PROPOSAL-06 | B15: Check Validity duration = -1 (below lower boundary) | C15: PRE: On the New proposal form with Customer = AAA Company. 1. Enter Validity duration = -1. 2. Click [Create draft]. 3. Check whether a proposal was created. | D15: An error is displayed and no proposal is created, because a validity period cannot end before the proposal date. | E15: ADD_PROPOSAL-01
A16: ADD_PROPOSAL-07 | B16: Check Validity duration = 1 (minimum valid value) | C16: PRE: On the New proposal form with Customer = AAA Company. 1. Enter Validity duration = 1. 2. Enter Note (internal) = QA23130284-C07-[RUN]. 3. Click [Create draft]. | D16: Draft proposal is created; Validity ending date = Date + 1 day. | E16: ADD_PROPOSAL-01
A17: ADD_PROPOSAL-08 | B17: Cancel the creation of a proposal | C17: PRE: Logged in to demo.dolibarr.org (user David Doe); third party 'AAA Company' exists. 1. Open Commercial > Proposals and note the number in the list title. 2. Click New proposal, select Customer = AAA Company. 3. Click [Cancel]. 4. Read the number in the list title again. | D17: User is taken back to the Commercial proposals list; the count is unchanged; no proposal is created. | E17: ADD_PROPOSAL-01
A18: PROPOSAL_LINE-01 | B18: Reject a free-text line without Type and Description | C18: PRE: A draft proposal tagged QA23130284 is open (created by ADD_PROPOSAL-02) and has no line. 1. In the add-line area select the radio 'Free-text item'. 2. Leave Type and Description empty; enter Unit price = 100, Qty = 1, VAT = 20%. 3. Click [Add]. | D18: Errors are displayed ("Field 'Type' is required", "Field 'Description' is required"); no line is added. | E18: ADD_PROPOSAL-02
A19: PROPOSAL_LINE-02 | B19: Add a valid free-text line (price 100, qty 1, VAT 20%) | C19: PRE: A draft proposal tagged QA23130284 is open (created by ADD_PROPOSAL-02) and has no line. 1. Select the radio 'Free-text item'; Type = Service. 2. Description = QA23130284 line 1; Unit price = 100; Qty = 1; VAT = 20%. 3. Click [Add]. | D19: Line is added: U.P. (net) 100.00; U.P. (inc. tax) 120.00; Qty 1; Total 100.00. Proposal amounts: excl. tax 100.00; tax 20.00; inc. tax 120.00. Button [Validate] becomes available. | E19: ADD_PROPOSAL-02
A20: PROPOSAL_LINE-03 | B20: Check Qty = -1 (below lower boundary) | C20: PRE: Draft proposal with line 'QA23130284 line 1' (created by PROPOSAL_LINE-02). 1. Select 'Free-text item'; Type = Service; Description = QA23130284 qty -1. 2. Enter Unit price = 100; Qty = -1; VAT = 20%. 3. Click [Add]. | D20: Error is displayed ("Field 'Qty' cannot be negative"); no line is added; entered values are kept in the form. | E20: PROPOSAL_LINE-02
A21: PROPOSAL_LINE-04 | B21: Reject Qty = non-numeric text | C21: PRE: Draft proposal with line 'QA23130284 line 1' (created by PROPOSAL_LINE-02). 1. Select 'Free-text item'; Type = Service; Description = QA23130284 qty abc. 2. Enter Unit price = 100; Qty = abc; VAT = 20%. 3. Click [Add]. | D21: An error is displayed and no line is added; proposal totals are unchanged. | E21: PROPOSAL_LINE-02
A22: PROPOSAL_LINE-05 | B22: Check Discount = 10% | C22: PRE: Draft proposal with line 'QA23130284 line 1' (created by PROPOSAL_LINE-02). 1. Select 'Free-text item'; Type = Service; Description = QA23130284 discount 10. 2. Enter Unit price = 100; Qty = 1; Discount = 10; VAT = 20%. 3. Click [Add]. | D22: Disc. column shows 10%; line total = 90.00. Proposal amounts increase by 90.00 (excl. tax) and 18.00 (tax). | E22: PROPOSAL_LINE-02
... A35: LIST_PROPOSAL-01 | B35: Filter the proposal list by an existing Ref | C35: PRE: A Signed proposal tagged QA23130284 exists (from PROPOSAL_STATUS-07); note its reference PRyymm-nnnn. 1. Open Commercial > Proposals. 2. Enter the noted reference in the Ref filter and press Enter. | D35: Exactly one row is listed: that reference, Customer = AAA Company, Status = Signed; the list title shows (1). | E35: PROPOSAL_STATUS-07
A36: LIST_PROPOSAL-02 | B36: Filter the proposal list by a non-existing Ref | C36: PRE: Logged in to demo.dolibarr.org (user David Doe). 1. Open Commercial > Proposals. 2. Enter Ref = ZZZ-NO-SUCH-REF and press Enter. | D36: Message 'No record found' is displayed; the list title shows (0).
A37: LIST_PROPOSAL-03 | B37: Combine Ref with Status and Amount filters | C37: PRE: Signed proposal tagged QA23130284 with amount 100.00 excl. tax; note its reference. 1. Filter Ref = that reference + Status = Signed. 2. Repeat with Status = Not signed, then Billed. 3. Repeat with Ref + Amount (excl. tax) = 100, then = 999. | D37: Status Signed -> 1 row; Not signed -> 0 rows; Billed -> 0 rows. Amount 100 -> 1 row; Amount 999 -> 0 rows. | E37: LIST_PROPOSAL-01
A38: LIST_PROPOSAL-04 | B38: Check the Status filter offers every status that can appear in the list | C38: PRE: A proposal tagged QA23130284 in status 'Canceled' exists (from PROPOSAL_STATUS-08). 1. Open Commercial > Proposals. 2. Open the Status filter drop-down and read its options. 3. Search the canceled proposal by Ref and read its Status. | D38: The drop-down contains every status, including 'Canceled'; the canceled proposal can be found by filtering on Canceled. | E38: PROPOSAL_STATUS-08

Sheet ProjectandTask
A1: Module Code | B1: Tasks_Management
A2: List | B2: Project & Tasks Management
A3: Test requirement | B3: Project and Task Management (Integrated 6 features)
A4: Tester | B4: Vo Quang Huy
A5: Passed | B5: 27
A6: Failed | B6: 0
A7: Untested | B7: 0
A8: Blocked | B8: 0
A9: Skipped | B9: 0
A10: Number of Test cases | B10: 27
A12: ID | B12: Test Case Description | C12: Test Case Procedure | D12: Expected Output | E12: Inter-test case Dependence | F12: Result | G12: Test date | H12: Note
A13: admin_Pro/Tasks_CreatePro_01 | B13: Verify creating a new project successfully when entering all valid information | C13: 1. On the home page, open the Projects menu and select New lead or project 2. Enter ref code = "PJ2610-0100", title = "Thiết kế Website", select third party = "11Transport", visibility = "Everybody", lead status = "Prospection" and enter lead amount = "5000" 3. Click Create project button | D13: 1. Projects management page is displayed 2. New lead or project creation form appears 3. 4. Project is created successfully with Draft status, the screen switches to detail page displaying all entered information 5. Displayed in Projects management
A14: admin_Pro/Tasks_CreatePro_02 | B14: Verify creating a project when filling only required field (title) | C14: 1. On the home page, open the Projects menu and select New lead or project 2. Enter title = "Dự án Báo cáo 02 tháng", leave optional fields blank 3. Click Create project button | D14: 1. Projects management page is displayed 2. New lead or project creation form appears 3. 4. Project is created successfully, system auto-generates ref code and saves in Draft status
A15: admin_Pro/Tasks_CreatePro_03 | B15: Verify error message when leaving required field (title) blank | C15: 1. On the home page, open the Projects menu and select New lead or project 2. Leave title blank, select third party = "11Transport" 3. Click Create project button | D15: 1. Projects management page is displayed 2. New lead or project creation form appears 3. 4. System displays error/warning message "Field 'Label/Title' is required" and prevents saving the project
A16: admin_Pro/Tasks_CreatePro_04 | B16: Verify creating a project with restricted view permission (project contacts only) | C16: 1. On the home page, open the Projects menu and select New lead or project 2. Enter title = "Dự án Tối mật Internal", select visibility = "Project contacts only" 3. Click Create project button | D16: 1. Projects management page is displayed 2. New lead or project creation form appears 3. 4. Project is created successfully and only accounts in the Project Contacts list have view permissions
A17: admin_Pro/Tasks_CreatePro_05 | B17: Verify Cancel button when entering data in the creation form | C17: 1. On the home page, open the Projects menu and select New lead or project 2. Enter data = "Dự án Thử nghiệm" 3. Click Cancel button | D17: 1. Projects management page is displayed 2. New lead or project creation form appears 3. 4. Creation operation is cancelled, data is not saved and system returns to the project list page
A18: admin_Pro/Tasks_CreatePro_06 | B18: Verify creating a project when unchecking both options: Follow opportunity and Follow tasks or time spent | C18: 1. On the home page, open the Projects menu and select New lead or project 2. Enter title = "Dự án Nội bộ Tham khảo" 3. Uncheck Follow opportunity and uncheck Follow tasks or time spent 4. Click Create project button | D18: 1. Projects management page is displayed 2. New lead or project creation form appears 3. 4. 5. Project is created successfully, detail page hides opportunity tracking (Lead) section and task/time management tools.
A19: admin_Pro/Tasks_CreatePro_07 | B19: Verify error message when checking Follow opportunity but leaving Lead status blank | C19: 1. On the home page, open the Projects menu and select New lead or project 2. Enter title = "Dự án Cơ hội Mới" 3. Check Follow opportunity and Follow tasks or time spent 4. Leave Lead status field blank 5. Click Create project button | D19: 1. Projects management page is displayed 2. New lead or project creation form appears 3. 4. 5. 6. System displays error message "You choose to follow an opportunity in this project, so you must also fill out the Lead status." and prevents project creation
A20: admin_Pro/Tasks_ValPro_01 | B20: Verify validating project directly from detail page (Draft to Open) | C20: 1. Open Projects list page and select a project currently in Draft status 2. Click Validate button at the bottom of the screen 3. When confirmation window appears, click Yes button | D20: 1. Project detail screen displays with grey Draft badge 2. Approval confirmation window appears 3. Project switches to Open status in green, Validate button disappears
A21: admin_Pro/Tasks_ValPro_02 | B21: Verify validating project by checking checkbox in list (bulk action) | C21: 1. Open Projects list page 2. Check the checkbox on the left of the project in Draft status (e.g. PJ2610-0005) 3. In the Select action box above, select Validate 4. Click Confirm button | D21: 1. Project list is displayed 2. Checkbox for project PJ2610-0005 is checked 3. Action list confirms Validate option 4. Project PJ2610-0005 is validated successfully, status changes from Draft to Open
A22: admin_Pro/Tasks_ValPro_03 | B22: Verify filtering list to retrieve only Draft projects for validation | C22: 1. Go to Projects list page 2. In the top-right Status filter box, click 'x' on Open tag to remove Open (keeping only Draft tag) 3. Click magnifying glass icon to search | D22: 1. Project list screen is displayed 2. Open tag is removed from filter, keeping only Draft tag 3. System displays list of all projects currently in Draft status
A23: admin_Pro/Tasks_ValPro_04 | B23: Verify error message when attempting to validate a project already in Open status | C23: 1. Go to Projects list page 2. Check the checkbox on the left of the project in Open status (e.g. PJ2610-0013) 3. In Select action box, select Validate 4. Click Confirm button | D23: 1. Project list screen is displayed 2. Checkbox for project PJ2610-0013 is checked 3. Screen displays action list 4. System displays error message "Object PJ2610-0013 must have status 'Draft' to be validated." and prevents re-validation
A24: admin_Pro/Tasks_CreateTask_01 | B24: Verify creating a new task or event successfully with full information | C24: 1. Go to Tasks/activities or Organized events menu and click New 2. Enter title = "Họp kế hoạch triển khai dự án" 3. Select type = "Meetings", select project = "PJ2610-0011, folio - Company Corp 1" 4. Click Create button | D24: 1. New creation page is displayed 2. Form Create an event displays all fields 3. 4. Event is created successfully and switches to detail page showing exact entered information
... A39: admin_Pro/Tasks_StatusPro_05 | B39: Verify returning project to draft using Back to draft button directly outside | C39: 1. On project detail page, click Back to draft button directly from action row at bottom 2. When confirmation window appears, click Confirm (or Yes) | D39: 1. Return to draft confirmation dialog box displays 2. Project status changes to Draft successfully and Validate button reappears

Sheet ContactAddress
A2: Module Code | B2: CONTACT | J2: Passed
A3: Test requirement | B3: Contact/Address | J3: Failed
A4: Tester | B4: Tran Anh Tuan | J4: Blocked
A5: Passed | B5: Failed | C5: Untested | D5: Blocked | E5: Skipped | F5: Number of Test cases | J5: Untested
A6: =COUNTIF(F9:F996,"Passed") -> 0 | B6: =COUNTIF(F9:F996,"Failed") -> 0 | C6: =F6-E6-D6-B6-A6 -> 30 | D6: =COUNTIF(F9:F996,"Blocked") -> 0 | E6: =COUNTIF(F9:F996,"Skipped") -> 0 | F6: =COUNTA(A9:A996) -> 30 | J6: Skipped
A8: ID | B8: Test Case Description | C8: Test Case Procedure | D8: Expected Output | E8: Inter-test case Dependence | F8: Result | G8: Test date | H8: Note
A9: ADD_CONTACT-01 | B9: Create a contact using the mandatory field only | C9: PRE: Signed in; last name QA23130372-C01-[RUN] does not exist. 1. Open Third parties > Contacts/Addresses > New Contact/Address. 2. Enter Last name / Label = QA23130372-C01-[RUN]. 3. Keep all optional fields blank and defaults unchanged. 4. Click ADD; open the saved contact card. | D9: Contact is created; the contact card shows the exact Last name entered; no optional field is required. | F9: Untested
A10: ADD_CONTACT-02 | B10: Create a contact with full information | C10: PRE: At least one third party exists. 1. Open Third parties > Contacts/Addresses > New Contact/Address. 2. Select Third party = an existing customer; enter Last name = QA23130372-C02-[RUN]; First name = Anh; Job position = QA Engineer. 3. Enter Address = 12 Nguyen Hue; Zip = 700000; Town = Ho Chi Minh; Country = Vietnam. 4. Enter Bus. phone = 0281234567; Mobile = 0901234567 (country code Vietnam +84); Email = qa.c02@example.com; Visibility = Shared; Date of birth = 15/05/2000. 5. Click ADD; review the contact card. | D10: Contact is created; every entered value is displayed on the contact card (birth date in the Personal data tab). | F10: Untested
A11: ADD_CONTACT-03 | B11: Reject creation when Last name is empty | C11: PRE: On New Contact/Address form. 1. Leave Last name / Label blank. 2. Enter First name = NoLastName. 3. Click ADD. 4. Check the message and the contact list. | D11: Creation is prevented; error "Field 'Last name / Label' is required" is shown; no new contact is added. | F11: Untested
A12: ADD_CONTACT-04 | B12: Reject a Last name containing only spaces | C12: PRE: On New Contact/Address form. 1. Enter Last name / Label = 5 spaces. 2. Click ADD. 3. Check the message and the contact list. | D12: Creation is prevented and Last name / Label is reported as required; no blank-named contact is created. | F12: Untested
A13: ADD_CONTACT-05 | B13: Reject an invalid email format | C13: PRE: On New Contact/Address form. 1. Enter Last name = QA23130372-C05-[RUN]. 2. Enter Email = qa.test@ (missing domain). 3. Click ADD. | D13: Creation is prevented; error "Email address qa.test@ is incorrect" is shown. | F13: Untested
A14: ADD_CONTACT-06 | B14: Accept a valid email containing special characters | C14: PRE: On New Contact/Address form. 1. Enter Last name = QA23130372-C06-[RUN]. 2. Enter Email = qa.tran+test@example.com. 3. Click ADD; review the card. | D14: Contact is created; the email is stored and displayed exactly as entered. | F14: Untested
A15: ADD_CONTACT-07 | B15: Last name with exactly 80 characters (upper boundary) | C15: PRE: On New Contact/Address form. 1. Enter Last name = 'QA23130372-C07-' followed by 'A' characters up to 80 characters in total. 2. Click ADD; review the card. | D15: Contact is created; the full 80-character Last name is displayed. | F15: Untested
A16: ADD_CONTACT-08 | B16: Last name with 81 characters (above boundary) | C16: PRE: On New Contact/Address form. 1. Paste an 81-character Last name starting with 'QA23130372-C08-'. 2. Observe the field length. 3. Click ADD; review the card. | D16: The field accepts at most 80 characters (maxlength = 80); the contact is saved with the first 80 characters only. | F16: Untested
A17: ADD_CONTACT-09 | B17: Create a contact with Vietnamese (Unicode) characters | C17: PRE: On New Contact/Address form. 1. Enter Last name = QA23130372-C09-Trần; First name = Ánh Tuấn. 2. Click ADD. 3. Check the card and the contact list. | D17: Contact is created; Vietnamese characters are displayed correctly on the card and in the list. | F17: Untested
A18: ADD_CONTACT-10 | B18: Do not execute HTML/script entered in Last name | C18: PRE: On New Contact/Address form. 1. Enter Last name = QA23130372-C10-<script>alert(1)</script>. 2. Click ADD. 3. Open the card and the contact list. | D18: Value is stored as plain text or the tags are stripped; no alert pop-up appears on the card or in the list. | F18: Untested
A19: ADD_CONTACT-11 | B19: Create a contact linked to a third party | C19: PRE: At least one third party exists. 1. Open Third parties > Contacts/Addresses > New Contact/Address. 2. Select Third party = an existing customer; enter Last name = QA23130372-C11-[RUN]. 3. Click ADD. 4. Open that third party > Contacts/Addresses tab. | D19: Contact is created and is listed in the Contacts/Addresses tab of the selected third party. | F19: Untested
A20: ADD_CONTACT-12 | B20: Correct a missing required field after validation | C20: PRE: On New Contact/Address form. 1. Enter First name = Recovery; leave Last name empty. 2. Click ADD and observe the required-field error. 3. Enter Last name = QA23130372-C12-[RUN]. 4. Click ADD again; inspect the card. | D20: First attempt is blocked; after entering Last name, exactly one contact is created and First name 'Recovery' is kept. | F20: Untested
A21: ADD_CONTACT-13 | B21: Cancel a filled New Contact/Address form | C21: PRE: On New Contact/Address form. 1. Enter Last name = QA23130372-C13-[RUN]. 2. Click CANCEL. 3. Open Third parties > Contacts/Addresses > List and search for QA23130372-C13. | D21: No contact is created; searching the list returns no record for {P}-C13. | E21: Fixture prepared before execution | F21: Untested
A22: LIST_CONTACT-01 | B22: Open the contact list and verify core columns | C22: PRE: Signed in. 1. Open Third parties > Contacts/Addresses > List. 2. Observe the table header and paging. | D22: List 'Contacts/Addresses (n)' is displayed with columns Last name, First name, Phone, Mobile, Email, Third party, Alias Name, Visibility and Status, plus a filter row and paging. | F22: Untested
A23: LIST_CONTACT-02 | B23: Search a prepared contact by Last name | C23: PRE: Contact QA23130372-C01-[RUN] exists. 1. Open Third parties > Contacts/Addresses > List. 2. Type QA23130372-C01 in the Last name filter. 3. Click the search (magnifier) icon. | D23: Only contacts whose Last name contains '{P}-C01' are displayed. | E23: ADD_CONTACT-01 | F23: Untested
A24: LIST_CONTACT-03 | B24: Search a prepared contact by Email | C24: PRE: Contact with email qa.c02@example.com exists. 1. Open Third parties > Contacts/Addresses > List. 2. Type qa.c02 in the Email filter. 3. Click search. | D24: The contact {P}-C02-[RUN] is displayed; unrelated contacts are not listed. | E24: ADD_CONTACT-02 | F24: Untested
A25: LIST_CONTACT-04 | B25: Search with a keyword that does not exist | C25: PRE: Signed in. 1. Open Third parties > Contacts/Addresses > List. 2. Type ZZZ-NO-MATCH-999 in the Last name filter. 3. Click search. | D25: No record is returned (list shows 'No record found'). | F25: Untested
A26: LIST_CONTACT-05 | B26: Verify saved contact details after page reload | C26: PRE: Contact QA23130372-C02-[RUN] exists. 1. Open its contact card from the list. 2. Reload the page (F5). 3. Compare all fields with the data entered at creation. | D26: All saved values (third party, name, address, phones, email; birth date in Personal data tab) are unchanged after reload. | E26: ADD_CONTACT-02 | F26: Untested
A27: EDIT_CONTACT-01 | B27: Open MODIFY for an existing contact | C27: PRE: Contact QA23130372-C02-[RUN] exists. 1. Open the contact card. 2. Click MODIFY. | D27: Edit form opens with all current values pre-filled; SAVE and CANCEL buttons are available. | E27: ADD_CONTACT-02 | F27: Untested
A28: EDIT_CONTACT-02 | B28: Update Last name and Job position | C28: PRE: Contact QA23130372-C01-[RUN] exists. 1. Open the card > MODIFY. 2. Change Last name = QA23130372-U02-[RUN]; Job position = Tester. 3. Click SAVE; reload the card. | D28: Changes are saved and persist after reload; other fields are unchanged. | E28: ADD_CONTACT-01 | F28: Untested
A29: EDIT_CONTACT-03 | B29: Change the linked third party | C29: PRE: Contact QA23130372-C11-[RUN] is linked to third party A; third party B exists. 1. Open the card > MODIFY. 2. Select Third party = B. 3. Click SAVE. 4. Check the Contacts/Addresses tab of A and B. | D29: Contact now appears under third party B and no longer under third party A. | E29: ADD_CONTACT-11 | F29: Untested
A30: EDIT_CONTACT-04 | B30: Reject clearing Last name during update | C30: PRE: Contact QA23130372-C06-[RUN] exists. 1. Open the card > MODIFY. 2. Clear Last name / Label. 3. Click SAVE. | D30: Update is rejected; error "Field 'Name / Label' is required" is shown; stored data is unchanged. | E30: ADD_CONTACT-06 | F30: Untested
